Traceback (most recent call last):
  File "/Users/jvanscho/miniforge3/lib/python3.9/site-packages/jupyter_cache/executors/utils.py", line 51, in single_nb_execution
    executenb(
  File "/Users/jvanscho/miniforge3/lib/python3.9/site-packages/nbclient/client.py", line 1093, in execute
    return NotebookClient(nb=nb, resources=resources, km=km, **kwargs).execute()
  File "/Users/jvanscho/miniforge3/lib/python3.9/site-packages/nbclient/util.py", line 84, in wrapped
    return just_run(coro(*args, **kwargs))
  File "/Users/jvanscho/miniforge3/lib/python3.9/site-packages/nbclient/util.py", line 62, in just_run
    return loop.run_until_complete(coro)
  File "/Users/jvanscho/miniforge3/lib/python3.9/asyncio/base_events.py", line 642, in run_until_complete
    return future.result()
  File "/Users/jvanscho/miniforge3/lib/python3.9/site-packages/nbclient/client.py", line 559, in async_execute
    await self.async_execute_cell(
  File "/Users/jvanscho/miniforge3/lib/python3.9/site-packages/nbclient/client.py", line 854, in async_execute_cell
    self._check_raise_for_error(cell, exec_reply)
  File "/Users/jvanscho/miniforge3/lib/python3.9/site-packages/nbclient/client.py", line 756, in _check_raise_for_error
    raise CellExecutionError.from_cell_and_msg(cell, exec_reply_content)
nbclient.exceptions.CellExecutionError: An error occurred while executing the following cell:
------------------
## Model solution
from sklearn.ensemble import RandomForestClassifier, GradientBoostingClassifier
from sklearn.model_selection import cross_val_score, train_test_split
from sklearn.metrics import balanced_accuracy_score
from xgboost import XGBClassifier

def evaluate_RF(X, y, n_estimators, max_depth=[2,8,32,64], scoring='accuracy'):
    """ Evaluate a Random Forest classifier using 3-fold cross-validation on the provided (X, y) data. 
    Keyword arguments:
    X -- the data for training and testing
    y -- the correct labels
    n_estimators -- the value for the gamma parameter
    
    Returns: a dictionary with the train and test score, e.g. {"rf_1": 0.9, "rf_2": 0.95}
    """
    res = {}
    for md in max_depth:
        rf = RandomForestClassifier(n_estimators=n_estimators, max_depth=md, random_state=1)
        res['rf_'+str(md)] = np.mean(cross_val_score(rf,X,y,cv=3,scoring=scoring))
    return res
------------------

[0;31m---------------------------------------------------------------------------[0m
[0;31mModuleNotFoundError[0m                       Traceback (most recent call last)
[0;32m/var/folders/0t/5d8ttqzd773fy0wq3h5db0xr0000gn/T/ipykernel_84533/3873894924.py[0m in [0;36m<module>[0;34m[0m
[1;32m      3[0m [0;32mfrom[0m [0msklearn[0m[0;34m.[0m[0mmodel_selection[0m [0;32mimport[0m [0mcross_val_score[0m[0;34m,[0m [0mtrain_test_split[0m[0;34m[0m[0;34m[0m[0m
[1;32m      4[0m [0;32mfrom[0m [0msklearn[0m[0;34m.[0m[0mmetrics[0m [0;32mimport[0m [0mbalanced_accuracy_score[0m[0;34m[0m[0;34m[0m[0m
[0;32m----> 5[0;31m [0;32mfrom[0m [0mxgboost[0m [0;32mimport[0m [0mXGBClassifier[0m[0;34m[0m[0;34m[0m[0m
[0m[1;32m      6[0m [0;34m[0m[0m
[1;32m      7[0m [0;32mdef[0m [0mevaluate_RF[0m[0;34m([0m[0mX[0m[0;34m,[0m [0my[0m[0;34m,[0m [0mn_estimators[0m[0;34m,[0m [0mmax_depth[0m[0;34m=[0m[0;34m[[0m[0;36m2[0m[0;34m,[0m[0;36m8[0m[0;34m,[0m[0;36m32[0m[0;34m,[0m[0;36m64[0m[0;34m][0m[0;34m,[0m [0mscoring[0m[0;34m=[0m[0;34m'accuracy'[0m[0;34m)[0m[0;34m:[0m[0;34m[0m[0;34m[0m[0m

[0;31mModuleNotFoundError[0m: No module named 'xgboost'
ModuleNotFoundError: No module named 'xgboost'

