Traceback (most recent call last):
  File "/Users/jvanscho/miniforge3/lib/python3.9/site-packages/jupyter_cache/executors/utils.py", line 51, in single_nb_execution
    executenb(
  File "/Users/jvanscho/miniforge3/lib/python3.9/site-packages/nbclient/client.py", line 1093, in execute
    return NotebookClient(nb=nb, resources=resources, km=km, **kwargs).execute()
  File "/Users/jvanscho/miniforge3/lib/python3.9/site-packages/nbclient/util.py", line 84, in wrapped
    return just_run(coro(*args, **kwargs))
  File "/Users/jvanscho/miniforge3/lib/python3.9/site-packages/nbclient/util.py", line 62, in just_run
    return loop.run_until_complete(coro)
  File "/Users/jvanscho/miniforge3/lib/python3.9/asyncio/base_events.py", line 642, in run_until_complete
    return future.result()
  File "/Users/jvanscho/miniforge3/lib/python3.9/site-packages/nbclient/client.py", line 559, in async_execute
    await self.async_execute_cell(
  File "/Users/jvanscho/miniforge3/lib/python3.9/site-packages/nbclient/client.py", line 854, in async_execute_cell
    self._check_raise_for_error(cell, exec_reply)
  File "/Users/jvanscho/miniforge3/lib/python3.9/site-packages/nbclient/client.py", line 756, in _check_raise_for_error
    raise CellExecutionError.from_cell_and_msg(cell, exec_reply_content)
nbclient.exceptions.CellExecutionError: An error occurred while executing the following cell:
------------------
# Auto-setup when running on Google Colab
if 'google.colab' in str(get_ipython()):
    !pip install openml

# General imports
%matplotlib inline
import numpy as np
import pandas as pd
import matplotlib.pyplot as plt
import openml as oml
from matplotlib import cm

# Hide convergence warning for now
import warnings
from sklearn.exceptions import ConvergenceWarning
warnings.filterwarnings("ignore", category=ConvergenceWarning)

# Hiding all warnings. Not recommended, just for compilation.
if not sys.warnoptions:
    warnings.simplefilter("ignore")
    os.environ["PYTHONWARNINGS"] = "ignore"
------------------

[0;31m---------------------------------------------------------------------------[0m
[0;31mNameError[0m                                 Traceback (most recent call last)
[0;32m/var/folders/0t/5d8ttqzd773fy0wq3h5db0xr0000gn/T/ipykernel_60052/2913392356.py[0m in [0;36m<module>[0;34m[0m
[1;32m     17[0m [0;34m[0m[0m
[1;32m     18[0m [0;31m# Hiding all warnings. Not recommended, just for compilation.[0m[0;34m[0m[0;34m[0m[0m
[0;32m---> 19[0;31m [0;32mif[0m [0;32mnot[0m [0msys[0m[0;34m.[0m[0mwarnoptions[0m[0;34m:[0m[0;34m[0m[0;34m[0m[0m
[0m[1;32m     20[0m     [0mwarnings[0m[0;34m.[0m[0msimplefilter[0m[0;34m([0m[0;34m"ignore"[0m[0;34m)[0m[0;34m[0m[0;34m[0m[0m
[1;32m     21[0m     [0mos[0m[0;34m.[0m[0menviron[0m[0;34m[[0m[0;34m"PYTHONWARNINGS"[0m[0;34m][0m [0;34m=[0m [0;34m"ignore"[0m[0;34m[0m[0;34m[0m[0m

[0;31mNameError[0m: name 'sys' is not defined
NameError: name 'sys' is not defined

